Workbook

Sheet Pre-requisite
A1: S.No. | B1: Pre-requisite to be provided by all the sites
A2: 1 | B2: Electricity invoices for meters installed at Plant premises, Stockyard, Guest Houses and Office locations for FY 25-26 and Apr-26 to Jun-26
A3: 2 | B3: Solar invoices for meters installed at Plant premises for FY 25-26 and Apr-26 to Jun-26
A4: 3 | B4: Complete SAP Dump during FY 2025-26 & Apr-26 to Jun-26 for the following:
B5: - Biomass purchased
B6: - LPG purchased
B7: - Petrol & Diesel Consumption (including Own Vehciles)
A8: 4 | B8: Calibration certificate valid during FY 25-26 for Diesel/ Petrol consumption (in case the consumption is not invoiced based)
A11: Please note sample invoices will be requested from the SAP Dump for the following - Biomass, LPG, Petrol/ Diesel
A13: Requirement from Corporate Office
A14: 1 | B14: Complete Power & Fuel Dump with INR, fuel/ power purchased, plant code and quantity procured information. (The INR value should tally the scrap sale as per the financials)

Sheet Energy Template - Consol
B1: Tata Steel Downstream Products Limited | F1: Inputs to be filled by TSDPL
B3: Table 1-Summary of Energy Consumption reported
B4: Parameter | F4: UOM | G4: As per Statement of BRSR Core
G5: A
B6: From renewable sources
B7: Total electricity consumption (A) | F7: GJ | G7: =M33 -> 0
B8: Total fuel consumption (B) | F8: GJ | G8: =SUM(M34) -> 0
B9: Energy consumption through other sources (C) | F9: GJ | G9: 0
B10: Total energy consumed from renewable sources (A+B+C) | F10: GJ | G10: =SUM(G7:G9) -> 0
B11: From non-renewable sources
B12: Total electricity consumption (D) | F12: GJ | G12: =M35 -> 0
B13: Total fuel consumption (E) | F13: GJ | G13: =SUM(M36:M39) -> 0
B14: Energy consumption through other sources (F) | F14: GJ | G14: 0
B15: Total energy consumed from non-renewable sources (D+E+F) | F15: GJ | G15: =SUM(G12:G14) -> 0
B16: Total energy consumed (A+B+C+D+E+F) | F16: GJ | G16: =G10+G15 -> 0
B17: Energy intensity per rupee of turnover adjusted for Purchasing Power Parity (PPP) | F17: GJ/USD | G17: #DIV/0!
B20: Table 2: % of energy consumed from renewable sources
B21: Particulars | C21: Unit | D21: As per Statement of BRSR Core
D22: A
B23: Energy consumed through renewable sources (A) | C23: GJ | D23: =G10 -> 0
B24: Total Energy consumption (B) | C24: GJ | D24: =G16 -> 0
B25: Percentage of energy consumed from renewable sources | C25: % | D25: =D23/D24% -> #DIV/0!
B28: Table 3- Energy Consumption for the year 2025-26 (in GJ) | J28: To be filled at Corporate Level to ensure consistency in the conversion factors
B30: Parameter | C30: Source of Energy | D30: Plant | E30: Guest Houses | F30: Offices | G30: Stockyard | H30: Total Consumption | I30: UoM | J30: Conversion Factor | K30: Source Name for such Conversion Factor | L30: Units | M30: Total Energy Consumption (in GJ)
D31: B | E31: C | F31: D | G31: E | H31: F= B+C+D+E | J31: G | M31: H= F*G
B33: Renewable: Electricity | C33: Electricity-Solar | D33: =SUM(E49:N49) -> 0 | E33: =SUM(Q49) -> 0 | F33: =SUM(O49) -> 0 | G33: =SUM(P49) -> 0 | H33: =D33+E33+F33+G33 -> 0 | I33: kWh | L33: GJ per kWh | M33: =H33*J33 -> 0
B34: Renewable: Fuel | C34: Briquette- Biomass | D34: =SUM(E50:N50) -> 0 | E34: =SUM(Q50) -> 0 | F34: =SUM(O50) -> 0 | G34: =SUM(P50) -> 0 | H34: =D34+E34+F34+G34 -> 0 | I34: kg | L34: GJ per kg | M34: =H34*J34 -> 0
B35: Non-renewable: Electricity | C35: Electricity-Grid | D35: =SUM(E51:N51) -> 0 | E35: =SUM(Q51) -> 0 | F35: =SUM(O51) -> 0 | G35: =SUM(P51) -> 0 | H35: =D35+E35+F35+G35 -> 0 | I35: kWh | L35: GJ per kWh | M35: =H35*J35 -> 0
B36: Non-renewable: Fuel | C36: Diesel | D36: =SUM(E52:N52) -> 0 | E36: =SUM(Q52) -> 0 | F36: =SUM(O52) -> 0 | G36: =SUM(P52) -> 0 | H36: =D36+E36+F36+G36 -> 0 | I36: kL | L36: GJ per KL | M36: =H36*J36 -> 0
B37: Non-renewable: Fuel | C37: LPG | D37: =SUM(E53:N53) -> 0 | E37: =SUM(Q53) -> 0 | F37: =SUM(O53) -> 0 | G37: =SUM(P53) -> 0 | H37: =D37+E37+F37+G37 -> 0 | I37: kg | L37: GJ per kg | M37: =H37*J37 -> 0
B38: Non-renewable: Fuel | C38: Petrol | D38: =SUM(E54:N54) -> 0 | E38: =SUM(Q54) -> 0 | F38: =SUM(O54) -> 0 | G38: =SUM(P54) -> 0 | H38: =D38+E38+F38+G38 -> 0 | I38: kL | L38: GJ per kL | M38: =H38*J38 -> 0
B39: Non-renewable: Fuel | C39: Natural Gas | D39: =SUM(E55:N55) -> 0 | E39: =SUM(Q55) -> 0 | F39: =SUM(O55) -> 0 | G39: =SUM(P55) -> 0 | H39: =D39+E39+F39+G39 -> 0 | M39: =H39*J39 -> 0
B40: Non-renewable: Fuel | C40: Propane | D40: =SUM(E56:N56) -> 0 | E40: =SUM(Q56) -> 0 | F40: =SUM(O56) -> 0 | G40: =SUM(P56) -> 0 | H40: =D40+E40+F40+G40 -> 0 | M40: =H40*J40 -> 0
B41: Non-renewable: Fuel | C41: Acetylene (if used as fuel for cutting/heating) | D41: =SUM(E57:N57) -> 0 | E41: =SUM(Q57) -> 0 | F41: =SUM(O57) -> 0 | G41: =SUM(P57) -> 0 | H41: =D41+E41+F41+G41 -> 0 | M41: =H41*J41 -> 0
B42: Renewable/ Non-renewable: Fuel | C42: Any Other Fuel | D42: =SUM(E58:N58) -> 0 | E42: =SUM(Q58) -> 0 | F42: =SUM(O58) -> 0 | G42: =SUM(P58) -> 0 | H42: =D42+E42+F42+G42 -> 0 | M42: =H42*J42 -> 0
B45: Table 3.1
B46: Summary of Energy Consumption
B47: Parameter | C47: Source of Energy | D47: UoM | E47: CR | F47: Bara | G47: Demag | H47: Chennai | I47: Faridabad | J47: Pune | K47: Kalinganagar | L47: Pantnagar | M47: Tada | N47: Sanand | O47: Offices | P47: Stockyard | Q47: Guest House | R47: Total
B49: Renewable: Electricity | C49: Electricity-Solar | D49: kWh | E49: ='CR-Jamshedpur'!E7 -> 0 | F49: ='Bara-Jamshedpur'!E7 -> 0 | G49: ='Demag-Jamshedpur'!E7 -> 0 | H49: =Chennai!E7 -> 0 | I49: =Faridabad!E7 -> 0 | J49: =Pune!E7 -> 0 | K49: =Kalinganagar!E7 -> 0 | L49: =Pantnagar!E7 -> 0 | M49: =Tada!E7 -> 0 | N49: =Sanand!E7 -> 0 | O49: ='Offices, Stockyard&Guest House'!Q7 -> 0 | P49: ='Offices, Stockyard&Guest House'!R7 -> 0 | Q49: ='Offices, Stockyard&Guest House'!S7 -> 0 | R49: =SUM(E49:Q49) -> 0
B50: Renewable: Fuel | C50: Biomass | D50: Kg | E50: ='CR-Jamshedpur'!E8 -> 0 | F50: ='Bara-Jamshedpur'!E8 -> 0 | G50: ='Demag-Jamshedpur'!E8 -> 0 | H50: =Chennai!E8 -> 0 | I50: =Faridabad!E8 -> 0 | J50: =Pune!E8 -> 0 | K50: =Kalinganagar!E8 -> 0 | L50: =Pantnagar!E8 -> 0 | M50: =Tada!E8 -> 0 | N50: =Sanand!E8 -> 0 | O50: 0 | P50: 0 | Q50: 0 | R50: =SUM(E50:Q50) -> 0
...

Sheet PPP calculation
B1: Tata Steel Downstream Products Limited | E1: Inputs to be filled by TSDPL
B3: Table- Calculation of PPP
B4: Parameter | C4: Data Points | D4: UoM | E4: FY 2025-26
B5: Energy intensity per rupee of turnover adjusted for PPP | C5: Total energy consumed | D5: GJ | E5: ='Energy Template - Consol'!G16 -> 0
C6: Revenue from operations | D6: INR
C7: PPP conversion factor (national currency per US dollar) | D7: INR/USD
C8: Revenue from operations adjusted for PPP | D8: USD | E8: =E6/E7 -> #DIV/0!
C9: Energy intensity per rupee of turnover adjusted for PPP | D9: GJ/ USD | E9: =E5/E8 -> #DIV/0!
B12: NOTE: | C12: We, the members of TSDPL Management, agree and confirm that this document has been thoroughly reviewed and that the data inputs provided above are accurate and complete.
B13: Name of Data Input Person in this sheet
B14: Name of Reviewer of this sheet

Sheet CR-Jamshedpur
B1: Tata Steel Downstream Products Limited | F1: Inputs to be filled by TSDPL
B3: Table 1
B4: Summary of Energy Consumption
B5: Parameter | C5: Source of Energy | D5: UoM | E5: CR-Jamshedpur
E6: Total Consumption (Q1 FY27) | F6: <<Site team to ensure that the total consumption is equal to the consumption mentioned in GHG template>>
B7: Renewable: Electricity | C7: Electricity-Solar | D7: kWh
B8: Renewable: Fuel | C8: Biomass | D8: Kg
B9: Non-renewable: Electricity | C9: Electricity-Grid | D9: kWh
B10: Non-renewable: Fuel | C10: Diesel | D10: kL
B11: Non-renewable: Fuel | C11: LPG | D11: Kg
B12: Non-renewable: Fuel | C12: Petrol | D12: kL
B13: Non-renewable: Fuel | C13: Natural Gas | D13: Kg
B14: Non-renewable: Fuel | C14: Propane | D14: Kg
B15: Non-renewable: Fuel | C15: Acetylene (if used as fuel for cutting/heating) | D15: Kg
B16: Renewable/ Non-renewable: Fuel | C16: Any Other Fuel | D16: Kg
B19: NOTE: | C19: We, the members of TSDPL Management, agree and confirm that this document has been thoroughly reviewed and that the data inputs provided above are accurate and complete.
B20: Name of Data Input Person in this sheet
B21: Name of Reviewer of this sheet

Sheet Bara-Jamshedpur
B1: Tata Steel Downstream Products Limited | F1: Inputs to be filled by TSDPL
B3: Table 1
B4: Summary of Energy Consumption
B5: Parameter | C5: Source of Energy | D5: UoM | E5: Bara
E6: Total Consumption (Q1 FY27) | F6: <<Site team to ensure that the total consumption is equal to the consumption mentioned in GHG template>>
B7: Renewable: Electricity | C7: Electricity-Solar | D7: kWh
B8: Renewable: Fuel | C8: Biomass | D8: Kg
B9: Non-renewable: Electricity | C9: Electricity-Grid | D9: kWh
B10: Non-renewable: Fuel | C10: Diesel | D10: kL
B11: Non-renewable: Fuel | C11: LPG | D11: Kg
B12: Non-renewable: Fuel | C12: Petrol | D12: kL
B13: Non-renewable: Fuel | C13: Natural Gas | D13: Kg
B14: Non-renewable: Fuel | C14: Propane | D14: Kg
B15: Non-renewable: Fuel | C15: Acetylene (if used as fuel for cutting/heating) | D15: Kg
B16: Renewable/ Non-renewable: Fuel | C16: Any Other Fuel | D16: Kg
B19: NOTE: | C19: We, the members of TSDPL Management, agree and confirm that this document has been thoroughly reviewed and that the data inputs provided above are accurate and complete.
B20: Name of Data Input Person in this sheet
B21: Name of Reviewer of this sheet

Sheet Demag-Jamshedpur
B1: Tata Steel Downstream Products Limited | F1: Inputs to be filled by TSDPL
B3: Table 1
B4: Summary of Energy Consumption
B5: Parameter | C5: Source of Energy | D5: UoM | E5: Demag
E6: Total Consumption (Q1 FY27) | F6: <<Site team to ensure that the total consumption is equal to the consumption mentioned in GHG template>>
B7: Renewable: Electricity | C7: Electricity-Solar | D7: kWh
B8: Renewable: Fuel | C8: Biomass | D8: Kg
B9: Non-renewable: Electricity | C9: Electricity-Grid | D9: kWh
B10: Non-renewable: Fuel | C10: Diesel | D10: kL
B11: Non-renewable: Fuel | C11: LPG | D11: Kg
B12: Non-renewable: Fuel | C12: Petrol | D12: kL
B13: Non-renewable: Fuel | C13: Natural Gas | D13: Kg
B14: Non-renewable: Fuel | C14: Propane | D14: Kg
B15: Non-renewable: Fuel | C15: Acetylene (if used as fuel for cutting/heating) | D15: Kg
B16: Renewable/ Non-renewable: Fuel | C16: Any Other Fuel | D16: Kg
B19: NOTE: | C19: We, the members of TSDPL Management, agree and confirm that this document has been thoroughly reviewed and that the data inputs provided above are accurate and complete.
B20: Name of Data Input Person in this sheet
B21: Name of Reviewer of this sheet

Sheet Chennai
B1: Tata Steel Downstream Products Limited | F1: Inputs to be filled by TSDPL
B3: Table 1
B4: Summary of Energy Consumption
B5: Parameter | C5: Source of Energy | D5: UoM | E5: Chennai
E6: Total Consumption | F6: <<Site team to ensure that the total consumption is equal to the consumption mentioned in GHG template>>
B7: Renewable: Electricity | C7: Electricity-Solar | D7: kWh
B8: Renewable: Fuel | C8: Biomass | D8: Kg
B9: Non-renewable: Electricity | C9: Electricity-Grid | D9: kWh
B10: Non-renewable: Fuel | C10: Diesel | D10: kL
B11: Non-renewable: Fuel | C11: LPG | D11: Kg
B12: Non-renewable: Fuel | C12: Petrol | D12: kL
B13: Non-renewable: Fuel | C13: Natural Gas
B14: Non-renewable: Fuel | C14: Propane
B15: Non-renewable: Fuel | C15: Acetylene (if used as fuel for cutting/heating)
B16: Renewable/ Non-renewable: Fuel | C16: Any Other Fuel
B19: NOTE: | C19: We, the members of TSDPL Management, agree and confirm that this document has been thoroughly reviewed and that the data inputs provided above are accurate and complete.
B20: Name of Data Input Person in this sheet
B21: Name of Reviewer of this sheet

Sheet Faridabad
B1: Tata Steel Downstream Products Limited | F1: Inputs to be filled by TSDPL
B3: Table 1
B4: Summary of Energy Consumption
B5: Parameter | C5: Source of Energy | D5: UoM | E5: Faridabad
E6: Total Consumption | F6: <<Site team to ensure that the total consumption is equal to the consumption mentioned in GHG template>>
B7: Renewable: Electricity | C7: Electricity-Solar | D7: kWh
B8: Renewable: Fuel | C8: Biomass | D8: Kg
B9: Non-renewable: Electricity | C9: Electricity-Grid | D9: kWh
B10: Non-renewable: Fuel | C10: Diesel | D10: kL
B11: Non-renewable: Fuel | C11: LPG | D11: Kg
B12: Non-renewable: Fuel | C12: Petrol | D12: kL
B13: Non-renewable: Fuel | C13: Natural Gas
B14: Non-renewable: Fuel | C14: Propane
B15: Non-renewable: Fuel | C15: Acetylene (if used as fuel for cutting/heating)
B16: Renewable/ Non-renewable: Fuel | C16: Any Other Fuel
B19: NOTE: | C19: We, the members of TSDPL Management, agree and confirm that this document has been thoroughly reviewed and that the data inputs provided above are accurate and complete.
B20: Name of Data Input Person in this sheet
B21: Name of Reviewer of this sheet

Sheet Pune
B1: Tata Steel Downstream Products Limited | F1: Inputs to be filled by TSDPL
B3: Table 1
B4: Summary of Energy Consumption
B5: Parameter | C5: Source of Energy | D5: UoM | E5: Pune
E6: Total Consumption | F6: <<Site team to ensure that the total consumption is equal to the consumption mentioned in GHG template>>
B7: Renewable: Electricity | C7: Electricity-Solar | D7: kWh
B8: Renewable: Fuel | C8: Biomass | D8: Kg
B9: Non-renewable: Electricity | C9: Electricity-Grid | D9: kWh
B10: Non-renewable: Fuel | C10: Diesel | D10: kL
B11: Non-renewable: Fuel | C11: LPG | D11: Kg
B12: Non-renewable: Fuel | C12: Petrol | D12: kL
B13: Non-renewable: Fuel | C13: Natural Gas
B14: Non-renewable: Fuel | C14: Propane
B15: Non-renewable: Fuel | C15: Acetylene (if used as fuel for cutting/heating) | D15: Kg
B16: Renewable/ Non-renewable: Fuel | C16: Any Other Fuel
B19: NOTE: | C19: We, the members of TSDPL Management, agree and confirm that this document has been thoroughly reviewed and that the data inputs provided above are accurate and complete.
B20: Name of Data Input Person in this sheet
B21: Name of Reviewer of this sheet

Sheet Pantnagar
B1: Tata Steel Downstream Products Limited | F1: Inputs to be filled by TSDPL
B3: Table 1
B4: Summary of Energy Consumption
B5: Parameter | C5: Source of Energy | D5: UoM | E5: Pantnagar
E6: Total Consumption | F6: <<Site team to ensure that the total consumption is equal to the consumption mentioned in GHG template>>
B7: Renewable: Electricity | C7: Electricity-Solar | D7: kWh
B8: Renewable: Fuel | C8: Biomass | D8: Kg
B9: Non-renewable: Electricity | C9: Electricity-Grid | D9: kWh
B10: Non-renewable: Fuel | C10: Diesel | D10: kL
B11: Non-renewable: Fuel | C11: LPG | D11: Kg
B12: Non-renewable: Fuel | C12: Petrol | D12: kL
B13: Non-renewable: Fuel | C13: Natural Gas
B14: Non-renewable: Fuel | C14: Propane
B15: Non-renewable: Fuel | C15: Acetylene (if used as fuel for cutting/heating)
B16: Renewable/ Non-renewable: Fuel | C16: Any Other Fuel
B19: NOTE: | C19: We, the members of TSDPL Management, agree and confirm that this document has been thoroughly reviewed and that the data inputs provided above are accurate and complete.
B20: Name of Data Input Person in this sheet
B21: Name of Reviewer of this sheet

Sheet Kalinganagar
B1: Tata Steel Downstream Products Limited | F1: Inputs to be filled by TSDPL
B3: Table 1
B4: Summary of Energy Consumption
B5: Parameter | C5: Source of Energy | D5: UoM | E5: Kalinganagar
E6: Total Consumption | F6: <<Site team to ensure that the total consumption is equal to the consumption mentioned in GHG template>>
B7: Renewable: Electricity | C7: Electricity-Solar | D7: kWh
B8: Renewable: Fuel | C8: Biomass | D8: Kg
B9: Non-renewable: Electricity | C9: Electricity-Grid | D9: kWh
B10: Non-renewable: Fuel | C10: Diesel | D10: kL
B11: Non-renewable: Fuel | C11: LPG | D11: Kg
B12: Non-renewable: Fuel | C12: Petrol | D12: kL
B13: Non-renewable: Fuel | C13: Natural Gas
B14: Non-renewable: Fuel | C14: Propane
B15: Non-renewable: Fuel | C15: Acetylene (if used as fuel for cutting/heating)
B16: Renewable/ Non-renewable: Fuel | C16: Any Other Fuel
B19: NOTE: | C19: We, the members of TSDPL Management, agree and confirm that this document has been thoroughly reviewed and that the data inputs provided above are accurate and complete.
B20: Name of Data Input Person in this sheet
B21: Name of Reviewer of this sheet

Sheet Tada
B1: Tata Steel Downstream Products Limited | F1: Inputs to be filled by TSDPL
B3: Table 1
B4: Summary of Energy Consumption
B5: Parameter | C5: Source of Energy | D5: UoM | E5: Tada
E6: Total Consumption | F6: <<Site team to ensure that the total consumption is equal to the consumption mentioned in GHG template>>
B7: Renewable: Electricity | C7: Electricity-Solar | D7: kWh
B8: Renewable: Fuel | C8: Biomass | D8: Kg
B9: Non-renewable: Electricity | C9: Electricity-Grid | D9: kWh
B10: Non-renewable: Fuel | C10: Diesel | D10: kL
B11: Non-renewable: Fuel | C11: LPG | D11: Kg
B12: Non-renewable: Fuel | C12: Petrol | D12: kL
B13: Non-renewable: Fuel | C13: Natural Gas
B14: Non-renewable: Fuel | C14: Propane
B15: Non-renewable: Fuel | C15: Acetylene (if used as fuel for cutting/heating) | D15: m3
B16: Renewable/ Non-renewable: Fuel | C16: Any Other Fuel-ACM | D16: m3
B19: NOTE: | C19: We, the members of TSDPL Management, agree and confirm that this document has been thoroughly reviewed and that the data inputs provided above are accurate and complete.
B20: Name of Data Input Person in this sheet
B21: Name of Reviewer of this sheet

Sheet Sanand
B1: Tata Steel Downstream Products Limited | F1: Inputs to be filled by TSDPL
B3: Table 1
B4: Summary of Energy Consumption
B5: Parameter | C5: Source of Energy | D5: UoM | E5: Faridabad
E6: Total Consumption | F6: <<Site team to ensure that the total consumption is equal to the consumption mentioned in GHG template>>
B7: Renewable: Electricity | C7: Electricity-Solar | D7: kWh
B8: Renewable: Fuel | C8: Biomass | D8: Kg
B9: Non-renewable: Electricity | C9: Electricity-Grid | D9: kWh
B10: Non-renewable: Fuel | C10: Diesel | D10: kL
B11: Non-renewable: Fuel | C11: LPG | D11: Kg
B12: Non-renewable: Fuel | C12: Petrol | D12: kL
B13: Non-renewable: Fuel | C13: Natural Gas
B14: Non-renewable: Fuel | C14: Propane
B15: Non-renewable: Fuel | C15: Acetylene (if used as fuel for cutting/heating)
B16: Renewable/ Non-renewable: Fuel | C16: Any Other Fuel
B19: NOTE: | C19: We, the members of TSDPL Management, agree and confirm that this document has been thoroughly reviewed and that the data inputs provided above are accurate and complete.
B20: Name of Data Input Person in this sheet
B21: Name of Reviewer of this sheet

Sheet Offices, Stockyard&Guest House
B1: Tata Steel Downstream Products Limited | F1: Inputs to be filled by TSDPL
B3: Table 1
B4: Summary of Energy Consumption | E4: Offices | F4: Offices | G4: Offices | H4: Offices | I4: Offices | J4: Offices | K4: Offices | L4: Offices | M4: Offices | N4: Stockyard | O4: Guest House | P4: Guest House | Q4: Total Consumption - Offices | R4: Total Consumption - Stockyard | S4: Total Consumption - Guest Houses
B5: Parameter | C5: Source of Energy | D5: UoM | E5: Lucknow | F5: Ludhiana | G5: Kolkata - Corporate Office | H5: Pune | I5: Indore | J5: Bhubaneswar | K5: Bengaluru | L5: Chennai | M5: Any other office location | N5: Howrah | O5: Pantnagar | P5: Kalinganagar
B7: Renewable: Electricity | C7: Electricity-Solar | D7: kWh | Q7: =SUM(E7:M7) -> 0 | R7: =N7 -> 0 | S7: =SUM(O7:P7) -> 0
B8: Non-renewable: Electricity | C8: Electricity-Grid | D8: kWh | Q8: =SUM(E8:M8) -> 0 | R8: =N8 -> 0 | S8: =SUM(O8:P8) -> 0
B9: Non-renewable: Fuel | C9: Diesel | D9: kL | Q9: =SUM(E9:M9) -> 0 | R9: =N9 -> 0 | S9: =SUM(O9:P9) -> 0
B10: Non-renewable: Fuel | C10: Petrol | D10: kL | Q10: =SUM(E10:M10) -> 0 | R10: =N10 -> 0 | S10: =SUM(O10:P10) -> 0
B11: Non-renewable: Fuel | C11: LPG | D11: KG | Q11: =SUM(E11:M11) -> 0 | R11: =N11 -> 0 | S11: =SUM(O11:P11) -> 0
B12: Renewable/ Non-renewable: Fuel | C12: Any Other Fuel | Q12: =SUM(E12:M12) -> 0 | R12: =N12 -> 0 | S12: =SUM(O12:P12) -> 0
E14: <<Team to ensure that the total consumption is equal to the consumption mentioned in GHG template>>
B15: NOTE: | C15: We, the members of TSDPL Management, agree and confirm that this document has been thoroughly reviewed and that the data inputs provided above are accurate and complete.
B16: Name of Data Input Person in this sheet
B17: Name of Reviewer of this sheet
